Internal Server Error: /api/app/
Traceback (most recent call last):
  File "C:\Users\tecsc\AppData\Local\Programs\Python\Python313\Lib\site-packages\django\core\handlers\exception.py", line 55, in inner
    response = get_response(request)
  File "C:\Users\tecsc\AppData\Local\Programs\Python\Python313\Lib\site-packages\django\core\handlers\base.py", line 220, in _get_response
    response = response.render()
  File "C:\Users\tecsc\AppData\Local\Programs\Python\Python313\Lib\site-packages\django\template\response.py", line 114, in render
    self.content = self.rendered_content
                   ^^^^^^^^^^^^^^^^^^^^^
  File "C:\Users\tecsc\AppData\Local\Programs\Python\Python313\Lib\site-packages\rest_framework\response.py", line 74, in rendered_content
    ret = renderer.render(self.data, accepted_media_type, context)
  File "C:\Users\tecsc\AppData\Local\Programs\Python\Python313\Lib\site-packages\rest_framework\renderers.py", line 100, in render
    ret = json.dumps(
        data, cls=self.encoder_class,
        indent=indent, ensure_ascii=self.ensure_ascii,
        allow_nan=not self.strict, separators=separators
    )
  File "C:\Users\tecsc\AppData\Local\Programs\Python\Python313\Lib\site-packages\rest_framework\utils\json.py", line 25, in dumps
    return json.dumps(*args, **kwargs)
           ~~~~~~~~~~^^^^^^^^^^^^^^^^^
  File "C:\Users\tecsc\AppData\Local\Programs\Python\Python313\Lib\json\__init__.py", line 238, in dumps
    **kw).encode(obj)
          ~~~~~~^^^^^
  File "C:\Users\tecsc\AppData\Local\Programs\Python\Python313\Lib\json\encoder.py", line 200, in encode
    chunks = self.iterencode(o, _one_shot=True)
  File "C:\Users\tecsc\AppData\Local\Programs\Python\Python313\Lib\json\encoder.py", line 261, in iterencode
    return _iterencode(o, 0)
  File "C:\Users\tecsc\AppData\Local\Programs\Python\Python313\Lib\site-packages\rest_framework\utils\encoders.py", line 67, in default
    return super().default(obj)
           ~~~~~~~~~~~~~~~^^^^^
  File "C:\Users\tecsc\AppData\Local\Programs\Python\Python313\Lib\json\encoder.py", line 180, in default
    raise TypeError(f'Object of type {o.__class__.__name__} '
                    f'is not JSON serializable')
TypeError: Object of type ObjectId is not JSON serializable
"POST /api/app/ HTTP/1.1" 500 105809
Internal Server Error: /api/app/
Traceback (most recent call last):
  File "C:\Users\tecsc\AppData\Local\Programs\Python\Python313\Lib\site-packages\django\core\handlers\exception.py", line 55, in inner
    response = get_response(request)
  File "C:\Users\tecsc\AppData\Local\Programs\Python\Python313\Lib\site-packages\django\core\handlers\base.py", line 220, in _get_response
    response = response.render()
  File "C:\Users\tecsc\AppData\Local\Programs\Python\Python313\Lib\site-packages\django\template\response.py", line 114, in render
    self.content = self.rendered_content
                   ^^^^^^^^^^^^^^^^^^^^^
  File "C:\Users\tecsc\AppData\Local\Programs\Python\Python313\Lib\site-packages\rest_framework\response.py", line 74, in rendered_content
    ret = renderer.render(self.data, accepted_media_type, context)
  File "C:\Users\tecsc\AppData\Local\Programs\Python\Python313\Lib\site-packages\rest_framework\renderers.py", line 100, in render
    ret = json.dumps(
        data, cls=self.encoder_class,
        indent=indent, ensure_ascii=self.ensure_ascii,
        allow_nan=not self.strict, separators=separators
    )
  File "C:\Users\tecsc\AppData\Local\Programs\Python\Python313\Lib\site-packages\rest_framework\utils\json.py", line 25, in dumps
    return json.dumps(*args, **kwargs)
           ~~~~~~~~~~^^^^^^^^^^^^^^^^^
  File "C:\Users\tecsc\AppData\Local\Programs\Python\Python313\Lib\json\__init__.py", line 238, in dumps
    **kw).encode(obj)
          ~~~~~~^^^^^
  File "C:\Users\tecsc\AppData\Local\Programs\Python\Python313\Lib\json\encoder.py", line 200, in encode
    chunks = self.iterencode(o, _one_shot=True)
  File "C:\Users\tecsc\AppData\Local\Programs\Python\Python313\Lib\json\encoder.py", line 261, in iterencode
    return _iterencode(o, 0)
  File "C:\Users\tecsc\AppData\Local\Programs\Python\Python313\Lib\site-packages\rest_framework\utils\encoders.py", line 67, in default
    return super().default(obj)
           ~~~~~~~~~~~~~~~^^^^^
  File "C:\Users\tecsc\AppData\Local\Programs\Python\Python313\Lib\json\encoder.py", line 180, in default
    raise TypeError(f'Object of type {o.__class__.__name__} '
                    f'is not JSON serializable')
TypeError: Object of type ObjectId is not JSON serializable
"POST /api/app/ HTTP/1.1" 500 105406
Internal Server Error: /api/app/
Traceback (most recent call last):
  File "C:\Users\tecsc\AppData\Local\Programs\Python\Python313\Lib\site-packages\django\core\handlers\exception.py", line 55, in inner
    response = get_response(request)
  File "C:\Users\tecsc\AppData\Local\Programs\Python\Python313\Lib\site-packages\django\core\handlers\base.py", line 197, in _get_response
    response = wrapped_callback(request, *callback_args, **callback_kwargs)
  File "C:\Users\tecsc\AppData\Local\Programs\Python\Python313\Lib\site-packages\django\views\decorators\csrf.py", line 65, in _view_wrapper
    return view_func(request, *args, **kwargs)
  File "C:\Users\tecsc\AppData\Local\Programs\Python\Python313\Lib\site-packages\django\views\generic\base.py", line 104, in view
    return self.dispatch(request, *args, **kwargs)
           ~~~~~~~~~~~~~^^^^^^^^^^^^^^^^^^^^^^^^^^
  File "C:\Users\tecsc\AppData\Local\Programs\Python\Python313\Lib\site-packages\rest_framework\views.py", line 515, in dispatch
    response = self.handle_exception(exc)
  File "C:\Users\tecsc\AppData\Local\Programs\Python\Python313\Lib\site-packages\rest_framework\views.py", line 475, in handle_exception
    self.raise_uncaught_exception(exc)
    ~~~~~~~~~~~~~~~~~~~~~~~~~~~~~^^^^^
  File "C:\Users\tecsc\AppData\Local\Programs\Python\Python313\Lib\site-packages\rest_framework\views.py", line 486, in raise_uncaught_exception
    raise exc
  File "C:\Users\tecsc\AppData\Local\Programs\Python\Python313\Lib\site-packages\rest_framework\views.py", line 512, in dispatch
    response = handler(request, *args, **kwargs)
  File "C:\Users\tecsc\Desktop\RFT\Server_V2\rfto_server\api\views.py", line 20, in post
    metadata = dict(request.data['metadata'])
                    ~~~~~~~~~~~~^^^^^^^^^^^^
KeyError: 'metadata'
"POST /api/app/ HTTP/1.1" 500 88154
Internal Server Error: /api/app/
Traceback (most recent call last):
  File "C:\Users\tecsc\AppData\Local\Programs\Python\Python313\Lib\site-packages\django\core\handlers\exception.py", line 55, in inner
    response = get_response(request)
  File "C:\Users\tecsc\AppData\Local\Programs\Python\Python313\Lib\site-packages\django\core\handlers\base.py", line 197, in _get_response
    response = wrapped_callback(request, *callback_args, **callback_kwargs)
  File "C:\Users\tecsc\AppData\Local\Programs\Python\Python313\Lib\site-packages\django\views\decorators\csrf.py", line 65, in _view_wrapper
    return view_func(request, *args, **kwargs)
  File "C:\Users\tecsc\AppData\Local\Programs\Python\Python313\Lib\site-packages\django\views\generic\base.py", line 104, in view
    return self.dispatch(request, *args, **kwargs)
           ~~~~~~~~~~~~~^^^^^^^^^^^^^^^^^^^^^^^^^^
  File "C:\Users\tecsc\AppData\Local\Programs\Python\Python313\Lib\site-packages\rest_framework\views.py", line 515, in dispatch
    response = self.handle_exception(exc)
  File "C:\Users\tecsc\AppData\Local\Programs\Python\Python313\Lib\site-packages\rest_framework\views.py", line 475, in handle_exception
    self.raise_uncaught_exception(exc)
    ~~~~~~~~~~~~~~~~~~~~~~~~~~~~~^^^^^
  File "C:\Users\tecsc\AppData\Local\Programs\Python\Python313\Lib\site-packages\rest_framework\views.py", line 486, in raise_uncaught_exception
    raise exc
  File "C:\Users\tecsc\AppData\Local\Programs\Python\Python313\Lib\site-packages\rest_framework\views.py", line 512, in dispatch
    response = handler(request, *args, **kwargs)
  File "C:\Users\tecsc\Desktop\RFT\Server_V2\rfto_server\api\views.py", line 22, in post
    response = ApiController.run(rft_data, metadata)
  File "C:\Users\tecsc\Desktop\RFT\Server_V2\rfto_server\api\modules\apicontroller.py", line 40, in run
    return actions[action](rft_data)
           ~~~~~~~~~~~~~~~^^^^^^^^^^
  File "C:\Users\tecsc\Desktop\RFT\Server_V2\rfto_server\api\modules\apicontroller.py", line 66, in start_maintenence
    return ApiController.saveandreturn(rft_serializer,
           ~~~~~~~~~~~~~~~~~~~~~~~~~~~^^^^^^^^^^^^^^^^
                                       'Dados da RFT recuperados com sucesso!',
                                       ^^^^^^^^^^^^^^^^^^^^^^^^^^^^^^^^^^^^^^^^
                                       'Nenhuma RFT foi encontrada para essa TCU')
                                       ^^^^^^^^^^^^^^^^^^^^^^^^^^^^^^^^^^^^^^^^^^^
  File "C:\Users\tecsc\Desktop\RFT\Server_V2\rfto_server\api\modules\apicontroller.py", line 14, in saveandreturn
    if rft_serializer.is_valid():
       ~~~~~~~~~~~~~~~~~~~~~~~^^
  File "C:\Users\tecsc\AppData\Local\Programs\Python\Python313\Lib\site-packages\rest_framework\serializers.py", line 218, in is_valid
    assert hasattr(self, 'initial_data'), (
           ~~~~~~~^^^^^^^^^^^^^^^^^^^^^^
AssertionError: Cannot call `.is_valid()` as no `data=` keyword argument was passed when instantiating the serializer instance.
"POST /api/app/ HTTP/1.1" 500 110657
Internal Server Error: /api/app/
Traceback (most recent call last):
  File "C:\Users\tecsc\AppData\Local\Programs\Python\Python313\Lib\site-packages\mongoengine\base\fields.py", line 576, in to_mongo
    return ObjectId(str(value))
  File "C:\Users\tecsc\AppData\Local\Programs\Python\Python313\Lib\site-packages\bson\objectid.py", line 105, in __init__
    self.__validate(oid)
    ~~~~~~~~~~~~~~~^^^^^
  File "C:\Users\tecsc\AppData\Local\Programs\Python\Python313\Lib\site-packages\bson\objectid.py", line 193, in __validate
    _raise_invalid_id(oid)
    ~~~~~~~~~~~~~~~~~^^^^^
  File "C:\Users\tecsc\AppData\Local\Programs\Python\Python313\Lib\site-packages\bson\objectid.py", line 38, in _raise_invalid_id
    raise InvalidId(
    ...<2 lines>...
    )
bson.errors.InvalidId: '38128n9ex219' is not a valid ObjectId, it must be a 12-byte input or a 24-character hex string

During handling of the above exception, another exception occurred:

Traceback (most recent call last):
  File "C:\Users\tecsc\AppData\Local\Programs\Python\Python313\Lib\site-packages\django\core\handlers\exception.py", line 55, in inner
    response = get_response(request)
  File "C:\Users\tecsc\AppData\Local\Programs\Python\Python313\Lib\site-packages\django\core\handlers\base.py", line 197, in _get_response
    response = wrapped_callback(request, *callback_args, **callback_kwargs)
  File "C:\Users\tecsc\AppData\Local\Programs\Python\Python313\Lib\site-packages\django\views\decorators\csrf.py", line 65, in _view_wrapper
    return view_func(request, *args, **kwargs)
  File "C:\Users\tecsc\AppData\Local\Programs\Python\Python313\Lib\site-packages\django\views\generic\base.py", line 104, in view
    return self.dispatch(request, *args, **kwargs)
           ~~~~~~~~~~~~~^^^^^^^^^^^^^^^^^^^^^^^^^^
  File "C:\Users\tecsc\AppData\Local\Programs\Python\Python313\Lib\site-packages\rest_framework\views.py", line 515, in dispatch
    response = self.handle_exception(exc)
  File "C:\Users\tecsc\AppData\Local\Programs\Python\Python313\Lib\site-packages\rest_framework\views.py", line 475, in handle_exception
    self.raise_uncaught_exception(exc)
    ~~~~~~~~~~~~~~~~~~~~~~~~~~~~~^^^^^
  File "C:\Users\tecsc\AppData\Local\Programs\Python\Python313\Lib\site-packages\rest_framework\views.py", line 486, in raise_uncaught_exception
    raise exc
  File "C:\Users\tecsc\AppData\Local\Programs\Python\Python313\Lib\site-packages\rest_framework\views.py", line 512, in dispatch
    response = handler(request, *args, **kwargs)
  File "C:\Users\tecsc\Desktop\RFT\Server_V2\rfto_server\api\views.py", line 22, in post
    response = ApiController.run(rft_data, metadata)
  File "C:\Users\tecsc\Desktop\RFT\Server_V2\rfto_server\api\modules\apicontroller.py", line 40, in run
    return actions[action](rft_data)
           ~~~~~~~~~~~~~~~^^^^^^^^^^
  File "C:\Users\tecsc\Desktop\RFT\Server_V2\rfto_server\api\modules\apicontroller.py", line 76, in pause_maintenence
    if rft:
       ^^^
  File "C:\Users\tecsc\AppData\Local\Programs\Python\Python313\Lib\site-packages\mongoengine\queryset\base.py", line 221, in __bool__
    return self._has_data()
           ~~~~~~~~~~~~~~^^
  File "C:\Users\tecsc\AppData\Local\Programs\Python\Python313\Lib\site-packages\mongoengine\queryset\base.py", line 217, in _has_data
    return False if queryset.first() is None else True
                    ~~~~~~~~~~~~~~^^
  File "C:\Users\tecsc\AppData\Local\Programs\Python\Python313\Lib\site-packages\mongoengine\queryset\base.py", line 301, in first
    result = queryset[0]
             ~~~~~~~~^^^
  File "C:\Users\tecsc\AppData\Local\Programs\Python\Python313\Lib\site-packages\mongoengine\queryset\base.py", line 205, in __getitem__
    queryset._cursor[key],
    ^^^^^^^^^^^^^^^^
  File "C:\Users\tecsc\AppData\Local\Programs\Python\Python313\Lib\site-packages\mongoengine\queryset\base.py", line 1720, in _cursor
    self._cursor_obj = self._collection.find(self._query, **self._cursor_args)
                                             ^^^^^^^^^^^
  File "C:\Users\tecsc\AppData\Local\Programs\Python\Python313\Lib\site-packages\mongoengine\queryset\base.py", line 1769, in _query
    self._mongo_query = self._query_obj.to_query(self._document)
                        ~~~~~~~~~~~~~~~~~~~~~~~~^^^^^^^^^^^^^^^^
  File "C:\Users\tecsc\AppData\Local\Programs\Python\Python313\Lib\site-packages\mongoengine\queryset\visitor.py", line 91, in to_query
    query = query.accept(QueryCompilerVisitor(document))
  File "C:\Users\tecsc\AppData\Local\Programs\Python\Python313\Lib\site-packages\mongoengine\queryset\visitor.py", line 184, in accept
    return visitor.visit_query(self)
           ~~~~~~~~~~~~~~~~~~~^^^^^^
  File "C:\Users\tecsc\AppData\Local\Programs\Python\Python313\Lib\site-packages\mongoengine\queryset\visitor.py", line 80, in visit_query
    return transform.query(self.document, **query.query)
           ~~~~~~~~~~~~~~~^^^^^^^^^^^^^^^^^^^^^^^^^^^^^^
  File "C:\Users\tecsc\AppData\Local\Programs\Python\Python313\Lib\site-packages\mongoengine\queryset\transform.py", line 133, in query
    value = field.prepare_query_value(op, value)
  File "C:\Users\tecsc\AppData\Local\Programs\Python\Python313\Lib\site-packages\mongoengine\base\fields.py", line 583, in prepare_query_value
    return self.to_mongo(value)
           ~~~~~~~~~~~~~^^^^^^^
  File "C:\Users\tecsc\AppData\Local\Programs\Python\Python313\Lib\site-packages\mongoengine\base\fields.py", line 578, in to_mongo
    self.error(str(e))
    ~~~~~~~~~~^^^^^^^^
  File "C:\Users\tecsc\AppData\Local\Programs\Python\Python313\Lib\site-packages\mongoengine\base\fields.py", line 215, in error
    raise ValidationError(message, errors=errors, field_name=field_name)
mongoengine.errors.ValidationError: '38128n9ex219' is not a valid ObjectId, it must be a 12-byte input or a 24-character hex string
"POST /api/app/ HTTP/1.1" 500 169087
Internal Server Error: /api/app/
Traceback (most recent call last):
  File "C:\Users\tecsc\AppData\Local\Programs\Python\Python313\Lib\site-packages\django\core\handlers\exception.py", line 55, in inner
    response = get_response(request)
  File "C:\Users\tecsc\AppData\Local\Programs\Python\Python313\Lib\site-packages\django\core\handlers\base.py", line 197, in _get_response
    response = wrapped_callback(request, *callback_args, **callback_kwargs)
  File "C:\Users\tecsc\AppData\Local\Programs\Python\Python313\Lib\site-packages\django\views\decorators\csrf.py", line 65, in _view_wrapper
    return view_func(request, *args, **kwargs)
  File "C:\Users\tecsc\AppData\Local\Programs\Python\Python313\Lib\site-packages\django\views\generic\base.py", line 104, in view
    return self.dispatch(request, *args, **kwargs)
           ~~~~~~~~~~~~~^^^^^^^^^^^^^^^^^^^^^^^^^^
  File "C:\Users\tecsc\AppData\Local\Programs\Python\Python313\Lib\site-packages\rest_framework\views.py", line 515, in dispatch
    response = self.handle_exception(exc)
  File "C:\Users\tecsc\AppData\Local\Programs\Python\Python313\Lib\site-packages\rest_framework\views.py", line 475, in handle_exception
    self.raise_uncaught_exception(exc)
    ~~~~~~~~~~~~~~~~~~~~~~~~~~~~~^^^^^
  File "C:\Users\tecsc\AppData\Local\Programs\Python\Python313\Lib\site-packages\rest_framework\views.py", line 486, in raise_uncaught_exception
    raise exc
  File "C:\Users\tecsc\AppData\Local\Programs\Python\Python313\Lib\site-packages\rest_framework\views.py", line 512, in dispatch
    response = handler(request, *args, **kwargs)
  File "C:\Users\tecsc\Desktop\RFT\Server_V2\rfto_server\api\views.py", line 22, in post
    response = ApiController.run(rft_data, metadata)
  File "C:\Users\tecsc\Desktop\RFT\Server_V2\rfto_server\api\modules\apicontroller.py", line 40, in run
    return actions[action](rft_data)
           ~~~~~~~~~~~~~~~^^^^^^^^^^
  File "C:\Users\tecsc\Desktop\RFT\Server_V2\rfto_server\api\modules\apicontroller.py", line 77, in pause_maintenence
    rft_data['metadata']['congelada'] = True
    ~~~~~~~~^^^^^^^^^^^^
KeyError: 'metadata'
"POST /api/app/ HTTP/1.1" 500 97357
